Workbook

Sheet Summary
A1: SQL Validator — Test Report
A2: Component: AI Query Security & Validation Layer (Navodya P G D, IT23144330) · J26-SE-347 · All queries run through the current validate() on 5 Oct 2026
A4: Total test queries | B4: =COUNTA('All Tests'!$A$2:$A$301) -> 300
A5: Expected BLOCKED (attacks) | B5: =COUNTIF('All Tests'!$F$2:$F$301,"BLOCKED") -> 162
A6: Expected SAFE (normal queries) | B6: =COUNTIF('All Tests'!$F$2:$F$301,"SAFE") -> 138
A7: Passed | B7: =COUNTIF('All Tests'!$H$2:$H$301,"PASS") -> 300
A8: Failed | B8: =COUNTIF('All Tests'!$H$2:$H$301,"FAIL") -> 0
A9: Pass rate | B9: =IF(B4=0,0,B7/B4) -> 1
A10: Attacks blocked (detection rate) | B10: =IF(B5=0,0,COUNTIFS('All Tests'!$F$2:$F$301,"BLOCKED",'All Tests'!$G$2:$G$301,"BLOCKED")/B5) -> 1
A11: Safe queries wrongly blocked (false-positive rate) | B11: =IF(B6=0,0,COUNTIFS('All Tests'!$F$2:$F$301,"SAFE",'All Tests'!$G$2:$G$301,"BLOCKED")/B6) -> 0
A12: From first test pass (23 Sep) | B12: =COUNTIF('All Tests'!$M$2:$M$301,"First test pass (23 Sep)") -> 235
A13: New for rules added in tuning | B13: =COUNTIF('All Tests'!$M$2:$M$301,"New rule (tuning)") -> 65
A15: Results by category
A16: Category | B16: Rule (violation type) | C16: What it tests | D16: Tests | E16: Expected BLOCKED | F16: Expected SAFE | G16: Passed | H16: Pass rate
A17: destructive_drop | B17: blocked_statement_type | C17: DROP TABLE deletes a whole table | D17: =COUNTIF('All Tests'!$B$2:$B$301,A17) -> 16 | E17: =COUNTIFS('All Tests'!$B$2:$B$301,A17,'All Tests'!$F$2:$F$301,"BLOCKED") -> 8 | F17: =COUNTIFS('All Tests'!$B$2:$B$301,A17,'All Tests'!$F$2:$F$301,"SAFE") -> 8 | G17: =COUNTIFS('All Tests'!$B$2:$B$301,A17,'All Tests'!$H$2:$H$301,"PASS") -> 16 | H17: =IF(D17=0,0,G17/D17) -> 1
A18: delete_no_where | B18: delete_without_where | C18: DELETE with no WHERE wipes every row | D18: =COUNTIF('All Tests'!$B$2:$B$301,A18) -> 16 | E18: =COUNTIFS('All Tests'!$B$2:$B$301,A18,'All Tests'!$F$2:$F$301,"BLOCKED") -> 8 | F18: =COUNTIFS('All Tests'!$B$2:$B$301,A18,'All Tests'!$F$2:$F$301,"SAFE") -> 8 | G18: =COUNTIFS('All Tests'!$B$2:$B$301,A18,'All Tests'!$H$2:$H$301,"PASS") -> 16 | H18: =IF(D18=0,0,G18/D18) -> 1
A19: truncate | B19: blocked_statement_type | C19: TRUNCATE empties a table | D19: =COUNTIF('All Tests'!$B$2:$B$301,A19) -> 12 | E19: =COUNTIFS('All Tests'!$B$2:$B$301,A19,'All Tests'!$F$2:$F$301,"BLOCKED") -> 6 | F19: =COUNTIFS('All Tests'!$B$2:$B$301,A19,'All Tests'!$F$2:$F$301,"SAFE") -> 6 | G19: =COUNTIFS('All Tests'!$B$2:$B$301,A19,'All Tests'!$H$2:$H$301,"PASS") -> 12 | H19: =IF(D19=0,0,G19/D19) -> 1
A20: update_no_where | B20: update_without_where | C20: UPDATE with no WHERE changes every row | D20: =COUNTIF('All Tests'!$B$2:$B$301,A20) -> 16 | E20: =COUNTIFS('All Tests'!$B$2:$B$301,A20,'All Tests'!$F$2:$F$301,"BLOCKED") -> 8 | F20: =COUNTIFS('All Tests'!$B$2:$B$301,A20,'All Tests'!$F$2:$F$301,"SAFE") -> 8 | G20: =COUNTIFS('All Tests'!$B$2:$B$301,A20,'All Tests'!$H$2:$H$301,"PASS") -> 16 | H20: =IF(D20=0,0,G20/D20) -> 1
A21: alter | B21: blocked_statement_type | C21: ALTER changes the table structure | D21: =COUNTIF('All Tests'!$B$2:$B$301,A21) -> 10 | E21: =COUNTIFS('All Tests'!$B$2:$B$301,A21,'All Tests'!$F$2:$F$301,"BLOCKED") -> 5 | F21: =COUNTIFS('All Tests'!$B$2:$B$301,A21,'All Tests'!$F$2:$F$301,"SAFE") -> 5 | G21: =COUNTIFS('All Tests'!$B$2:$B$301,A21,'All Tests'!$H$2:$H$301,"PASS") -> 10 | H21: =IF(D21=0,0,G21/D21) -> 1
A22: drop_database | B22: blocked_statement_type | C22: DROP DATABASE deletes everything | D22: =COUNTIF('All Tests'!$B$2:$B$301,A22) -> 5 | E22: =COUNTIFS('All Tests'!$B$2:$B$301,A22,'All Tests'!$F$2:$F$301,"BLOCKED") -> 5 | F22: =COUNTIFS('All Tests'!$B$2:$B$301,A22,'All Tests'!$F$2:$F$301,"SAFE") -> 0 | G22: =COUNTIFS('All Tests'!$B$2:$B$301,A22,'All Tests'!$H$2:$H$301,"PASS") -> 5 | H22: =IF(D22=0,0,G22/D22) -> 1
A23: unauthorized_write | B23: write_not_authorized | C23: Writes without the "authorize writes" flag | D23: =COUNTIF('All Tests'!$B$2:$B$301,A23) -> 8 | E23: =COUNTIFS('All Tests'!$B$2:$B$301,A23,'All Tests'!$F$2:$F$301,"BLOCKED") -> 8 | F23: =COUNTIFS('All Tests'!$B$2:$B$301,A23,'All Tests'!$F$2:$F$301,"SAFE") -> 0 | G23: =COUNTIFS('All Tests'!$B$2:$B$301,A23,'All Tests'!$H$2:$H$301,"PASS") -> 8 | H23: =IF(D23=0,0,G23/D23) -> 1
A24: stacked | B24: stacked_statements | C24: Two statements in one request (SELECT ...; DROP ...) | D24: =COUNTIF('All Tests'!$B$2:$B$301,A24) -> 16 | E24: =COUNTIFS('All Tests'!$B$2:$B$301,A24,'All Tests'!$F$2:$F$301,"BLOCKED") -> 8 | F24: =COUNTIFS('All Tests'!$B$2:$B$301,A24,'All Tests'!$F$2:$F$301,"SAFE") -> 8 | G24: =COUNTIFS('All Tests'!$B$2:$B$301,A24,'All Tests'!$H$2:$H$301,"PASS") -> 16 | H24: =IF(D24=0,0,G24/D24) -> 1
A25: tautology | B25: tautology_predicate | C25: Always-true conditions such as OR 1=1 | D25: =COUNTIF('All Tests'!$B$2:$B$301,A25) -> 24 | E25: =COUNTIFS('All Tests'!$B$2:$B$301,A25,'All Tests'!$F$2:$F$301,"BLOCKED") -> 12 | F25: =COUNTIFS('All Tests'!$B$2:$B$301,A25,'All Tests'!$F$2:$F$301,"SAFE") -> 12 | G25: =COUNTIFS('All Tests'!$B$2:$B$301,A25,'All Tests'!$H$2:$H$301,"PASS") -> 24 | H25: =IF(D25=0,0,G25/D25) -> 1
A26: comment_truncation | B26: sql_comment_present | C26: Comments that cut off the rest of the query | D26: =COUNTIF('All Tests'!$B$2:$B$301,A26) -> 16 | E26: =COUNTIFS('All Tests'!$B$2:$B$301,A26,'All Tests'!$F$2:$F$301,"BLOCKED") -> 8 | F26: =COUNTIFS('All Tests'!$B$2:$B$301,A26,'All Tests'!$F$2:$F$301,"SAFE") -> 8 | G26: =COUNTIFS('All Tests'!$B$2:$B$301,A26,'All Tests'!$H$2:$H$301,"PASS") -> 16 | H26: =IF(D26=0,0,G26/D26) -> 1
A27: union_exfiltration | B27: union_query | C27: UNION pulls in rows from another table | D27: =COUNTIF('All Tests'!$B$2:$B$301,A27) -> 16 | E27: =COUNTIFS('All Tests'!$B$2:$B$301,A27,'All Tests'!$F$2:$F$301,"BLOCKED") -> 8 | F27: =COUNTIFS('All Tests'!$B$2:$B$301,A27,'All Tests'!$F$2:$F$301,"SAFE") -> 8 | G27: =COUNTIFS('All Tests'!$B$2:$B$301,A27,'All Tests'!$H$2:$H$301,"PASS") -> 16 | H27: =IF(D27=0,0,G27/D27) -> 1
A28: dangerous_function | B28: dangerous_function | C28: SLEEP, LOAD_FILE, BENCHMARK, INTO OUTFILE ... | D28: =COUNTIF('All Tests'!$B$2:$B$301,A28) -> 19 | E28: =COUNTIFS('All Tests'!$B$2:$B$301,A28,'All Tests'!$F$2:$F$301,"BLOCKED") -> 13 | F28: =COUNTIFS('All Tests'!$B$2:$B$301,A28,'All Tests'!$F$2:$F$301,"SAFE") -> 6 | G28: =COUNTIFS('All Tests'!$B$2:$B$301,A28,'All Tests'!$H$2:$H$301,"PASS") -> 19 | H28: =IF(D28=0,0,G28/D28) -> 1
... A43: schema_allowlist | B43: table_not_allowed / column_not_allowed | C43: Only tables and columns on the allowlist | D43: =COUNTIF('All Tests'!$B$2:$B$301,A43) -> 13 | E43: =COUNTIFS('All Tests'!$B$2:$B$301,A43,'All Tests'!$F$2:$F$301,"BLOCKED") -> 7 | F43: =COUNTIFS('All Tests'!$B$2:$B$301,A43,'All Tests'!$F$2:$F$301,"SAFE") -> 6 | G43: =COUNTIFS('All Tests'!$B$2:$B$301,A43,'All Tests'!$H$2:$H$301,"PASS") -> 13 | H43: =IF(D43=0,0,G43/D43) -> 1
A44: Yellow = category added after the first test pass.
A46: What changed since the first test pass (23 Sep)
A47: Rules added | B47: system_schema_access, system_variable, locking_read, excessive_limit, too_many_tables, schema allowlist (table/column), more dangerous functions (EXTRACTVALUE, UPDATEXML, NAME_CONST, SYS_EXEC, SYS_EVAL, CONNECTION_ID).
A48: Rules improved | B48: Tautology check works out constant maths (OR 1, OR 2>1, OR id=id, OR NOT 0) and also checks HAVING and JOIN ... ON. Stacked queries now report stacked_statements.
A49: False alarm fixed | B49: # and -- inside quoted text (e.g. 'item #3') are no longer treated as comments.
A50: Behaviour change | B50: WHERE 1=1 AND tenant_id = 1 is now SAFE: the AND still filters rows. WHERE 1=1 alone and ... OR 1=1 stay BLOCKED.
A51: Regression found by this re-run | B51: comment-01..08 ('admin'--' ...) became SAFE after the comment fix; restored on 5 Oct 2026 by blocking any -- outside quotes.
A52: Implementation | B52: First pass ran on the earlier Python/sqlglot version; this run uses the Node.js node-sql-parser version, so some messages differ (see Note column).

Sheet How It Works
A1: What happens inside validate(sql)
A2: File: security_validation_layer_js/src/security-middleware.js — the checks run in this order on every query.
A4: Step | B4: Check | C4: In simple words
A5: 1 | B5: Look for stacked statements | C5: Before anything else, check the raw text for more than one statement (SELECT ...; DROP ...).
A6: 2 | B6: Parse into a tree (AST) | C6: node-sql-parser turns the SQL into a tree. If it cannot be parsed, the query is refused (parse_error). Example: SELECT name FROM customers WHERE id = 5 becomes SELECT -> columns: name, from: customers, where: id = 5.
A7: 3 | B7: Check the statement type | C7: Only SELECT by default. INSERT/UPDATE/DELETE only with Authorize Writes. DROP, TRUNCATE, ALTER, CREATE, GRANT, REVOKE, REPLACE: never.
A8: 4 | B8: Walk the whole tree for functions | C8: Every function call anywhere (also inside subqueries) is compared with the blocklist; INTO OUTFILE/DUMPFILE are checked as clauses.
A9: 5 | B9: System variables and schemas | C9: @@version-style variables and tables in information_schema / mysql / performance_schema / sys are refused.
A10: 6 | B10: Schema allowlist (when configured) | C10: Every table and column must be listed; SELECT * on a table with restricted columns is refused.
A11: 7 | B11: Always-true conditions | C11: Every WHERE, HAVING and JOIN ... ON is evaluated like MySQL would: if it, or any OR branch, is always true, it is refused.
A12: 8 | B12: Row locks and size | C12: FOR UPDATE / LOCK IN SHARE MODE, LIMIT above 10,000, more than 8 tables.
A13: 9 | B13: DELETE/UPDATE without WHERE, UNION, comments, nesting depth | C13: The remaining structural checks.
A14: 10 | B14: Verdict | C14: No violations -> SAFE. Any violation -> BLOCKED, with every reason listed (a query can have several).
A16: Why a tree and not plain text?
A17: A text search for "DROP" would miss "dRoP", extra spaces or comments, and would wrongly block a product called "Drop Shipping". The tree shows what the query really does, whatever it looks like.

Sheet Rules Explained
A1: Every rule in validate(), in simple words
A2: Each row is one "violation type" — the name the validator gives the problem it found.
A4: Violation type | B4: What it means | C4: Why it is dangerous | D4: Example that is BLOCKED | E4: Example that is SAFE | F4: Added
A5: blocked_statement_type | B5: The statement is a kind that is never allowed: DROP, TRUNCATE, ALTER, CREATE, GRANT, REVOKE, REPLACE (or anything that is not SELECT/INSERT/UPDATE/DELETE). | C5: These change or destroy the database itself, or give someone permissions. An AI should never need them to answer a question. | D5: DROP TABLE orders; | E5: SELECT * FROM orders WHERE id = 1; | F5: First pass
A6: write_not_authorized | B6: INSERT, UPDATE or DELETE when writes were not authorized for this request. | C6: By default the layer is read-only. Writes go through the Controlled Write Protocol (preview, approve, commit). | D6: UPDATE tickets SET status = 'closed' WHERE id = 2; | E6: Same query with Authorize Writes = TRUE | F6: First pass
A7: delete_without_where / update_without_where | B7: A DELETE or UPDATE with no WHERE clause. | C7: It would change or delete every row in the table. | D7: DELETE FROM orders; | E7: DELETE FROM orders WHERE id = 2; | F7: First pass
A8: stacked_statements | B8: Two or more statements in one request, separated by ; | C8: Classic injection: a harmless SELECT followed by a hidden DROP. | D8: SELECT * FROM orders; DROP TABLE orders; | E8: SELECT * FROM orders WHERE id = 2; | F8: First pass (now named)
A9: parse_error | B9: The SQL could not be turned into a tree (AST). | C9: If the validator cannot understand a query it cannot check it, so it refuses it (deny by default). | D9: SELECT * FROM WHERE; | E9: - | F9: First pass
A10: tautology_predicate | B10: A WHERE, HAVING or JOIN ... ON condition that is always true, or an OR branch that is always true. | C10: Makes the filter useless, so the query returns every row (including other tenants' or other users' data). | D10: SELECT * FROM orders WHERE id = 5 OR 2 > 1; | E10: SELECT * FROM orders WHERE 1=1 AND tenant_id = 1; | F10: Improved in tuning
A11: sql_comment_present | B11: A comment marker (--, #, /* */) outside quoted text. | C11: A comment can cut off the rest of the query, e.g. removing the password check in 'admin'-- ... | D11: SELECT * FROM users WHERE name = 'admin'--' AND password = 'x'; | E11: SELECT * FROM orders WHERE product = 'item #3'; | F11: Improved in tuning
A12: union_query | B12: The query uses UNION anywhere (also inside subqueries). | C12: UNION glues rows from a second, unrelated query onto the result, e.g. a password table. | D12: SELECT name FROM customers UNION SELECT password FROM admin_users; | E12: SELECT name FROM customers WHERE id = 1; | F12: First pass
A13: dangerous_function | B13: A function on the blocklist (config/dangerous_functions.json), or INTO OUTFILE / DUMPFILE. | C13: SLEEP/BENCHMARK slow the server; LOAD_FILE/OUTFILE read or write server files; USER()/VERSION() help attackers; EXTRACTVALUE/UPDATEXML leak data in error messages. | D13: SELECT LOAD_FILE('/etc/passwd'); | E13: SELECT CONCAT(product, ' - ', status) FROM orders; | F13: First pass + more in tuning
A14: excessive_subquery_depth | B14: Subqueries nested more than 6 levels deep. | C14: Real reports need 2-3 levels; deeper nesting is obfuscation or an attempt to overload the database. | D14: SELECT ... (7 nested SELECTs) | E14: SELECT ... (3 nested SELECTs) | F14: First pass
A15: system_schema_access | B15: The query reads MySQL's own system databases: information_schema, mysql, performance_schema, sys. | C15: information_schema maps every table and column; mysql.user holds password hashes. | D15: SELECT * FROM information_schema.tables; | E15: SELECT * FROM orders; | F15: Tuning
... A21: column_not_allowed | B21: A column not on the allowlist, or SELECT * on a table with restricted columns. | C21: Keeps sensitive columns such as password_hash out of every query, even when renamed or hidden in a subquery. | D21: SELECT password_hash FROM customers; | E21: SELECT id, name, email FROM customers; | F21: Tuning

Sheet All Tests
A1: ID | B1: Category | C1: SQL Query | D1: Authorize Writes | E1: Allowlist (svl_demo) | F1: Expected | G1: Actual Result | H1: Pass? | I1: Violation Types | J1: Violation Details | K1: First Pass Result (23 Sep) | L1: Note | M1: Source
A2: drop-01 | B2: destructive_drop | C2: DROP TABLE customers; | D2: FALSE | E2: FALSE | F2: BLOCKED | G2: BLOCKED | H2: =IF(G2=F2,"PASS","FAIL") -> PASS | I2: blocked_statement_type | J2: blocked_statement_type: DROP | K2: BLOCKED | M2: First test pass (23 Sep)
A3: drop-01-safe | B3: destructive_drop | C3: SELECT * FROM customers; | D3: FALSE | E3: FALSE | F3: SAFE | G3: SAFE | H3: =IF(G3=F3,"PASS","FAIL") -> PASS | I3: - | J3: - | K3: SAFE | M3: First test pass (23 Sep)
A4: drop-02 | B4: destructive_drop | C4: DROP TABLE orders; | D4: FALSE | E4: FALSE | F4: BLOCKED | G4: BLOCKED | H4: =IF(G4=F4,"PASS","FAIL") -> PASS | I4: blocked_statement_type | J4: blocked_statement_type: DROP | K4: BLOCKED | M4: First test pass (23 Sep)
A5: drop-02-safe | B5: destructive_drop | C5: SELECT * FROM orders; | D5: FALSE | E5: FALSE | F5: SAFE | G5: SAFE | H5: =IF(G5=F5,"PASS","FAIL") -> PASS | I5: - | J5: - | K5: SAFE | M5: First test pass (23 Sep)
A6: drop-03 | B6: destructive_drop | C6: DROP TABLE invoices; | D6: FALSE | E6: FALSE | F6: BLOCKED | G6: BLOCKED | H6: =IF(G6=F6,"PASS","FAIL") -> PASS | I6: blocked_statement_type | J6: blocked_statement_type: DROP | K6: BLOCKED | M6: First test pass (23 Sep)
A7: drop-03-safe | B7: destructive_drop | C7: SELECT * FROM invoices; | D7: FALSE | E7: FALSE | F7: SAFE | G7: SAFE | H7: =IF(G7=F7,"PASS","FAIL") -> PASS | I7: - | J7: - | K7: SAFE | M7: First test pass (23 Sep)
A8: drop-04 | B8: destructive_drop | C8: DROP TABLE employees; | D8: FALSE | E8: FALSE | F8: BLOCKED | G8: BLOCKED | H8: =IF(G8=F8,"PASS","FAIL") -> PASS | I8: blocked_statement_type | J8: blocked_statement_type: DROP | K8: BLOCKED | M8: First test pass (23 Sep)
A9: drop-04-safe | B9: destructive_drop | C9: SELECT * FROM employees; | D9: FALSE | E9: FALSE | F9: SAFE | G9: SAFE | H9: =IF(G9=F9,"PASS","FAIL") -> PASS | I9: - | J9: - | K9: SAFE | M9: First test pass (23 Sep)
A10: drop-05 | B10: destructive_drop | C10: DROP TABLE salaries; | D10: FALSE | E10: FALSE | F10: BLOCKED | G10: BLOCKED | H10: =IF(G10=F10,"PASS","FAIL") -> PASS | I10: blocked_statement_type | J10: blocked_statement_type: DROP | K10: BLOCKED | M10: First test pass (23 Sep)
A11: drop-05-safe | B11: destructive_drop | C11: SELECT * FROM salaries; | D11: FALSE | E11: FALSE | F11: SAFE | G11: SAFE | H11: =IF(G11=F11,"PASS","FAIL") -> PASS | I11: - | J11: - | K11: SAFE | M11: First test pass (23 Sep)
A12: drop-06 | B12: destructive_drop | C12: DROP TABLE products; | D12: FALSE | E12: FALSE | F12: BLOCKED | G12: BLOCKED | H12: =IF(G12=F12,"PASS","FAIL") -> PASS | I12: blocked_statement_type | J12: blocked_statement_type: DROP | K12: BLOCKED | M12: First test pass (23 Sep)
A13: drop-06-safe | B13: destructive_drop | C13: SELECT * FROM products; | D13: FALSE | E13: FALSE | F13: SAFE | G13: SAFE | H13: =IF(G13=F13,"PASS","FAIL") -> PASS | I13: - | J13: - | K13: SAFE | M13: First test pass (23 Sep)
... A84: unauth-write-08 | B84: unauthorized_write | C84: UPDATE contracts SET status = 'closed' WHERE id = 8; | D84: FALSE | E84: FALSE | F84: BLOCKED | G84: BLOCKED | H84: =IF(G84=F84,"PASS","FAIL") -> PASS | I84: write_not_authorized | J84: write_not_authorized: UPDATE | K84: BLOCKED | M84: First test pass (23 Sep)
A85: stacked-01 | B85: stacked | C85: SELECT * FROM customers WHERE id = 1; DROP TABLE customers; | D85: FALSE | E85: FALSE | F85: BLOCKED | G85: BLOCKED | H85: =IF(G85=F85,"PASS","FAIL") -> PASS | I85: stacked_statements, parse_error | J85: stacked_statements: Multiple SQL statements found in one request, parse_error: Multiple statements (2) in a single request are not allowed | K85: BLOCKED | L85: Now also reports stacked_statements (first pass only said parse_error). | M85: First test pass (23 Sep)
A86: stacked-01-safe | B86: stacked | C86: SELECT * FROM customers WHERE id = 1; | D86: FALSE | E86: FALSE | F86: SAFE | G86: SAFE | H86: =IF(G86=F86,"PASS","FAIL") -> PASS | I86: - | J86: - | K86: SAFE | M86: First test pass (23 Sep)
A87: stacked-02 | B87: stacked | C87: SELECT * FROM orders WHERE id = 2; DROP TABLE orders; | D87: FALSE | E87: FALSE | F87: BLOCKED | G87: BLOCKED | H87: =IF(G87=F87,"PASS","FAIL") -> PASS | I87: stacked_statements, parse_error | J87: stacked_statements: Multiple SQL statements found in one request, parse_error: Multiple statements (2) in a single request are not allowed | K87: BLOCKED | L87: Now also reports stacked_statements (first pass only said parse_error). | M87: First test pass (23 Sep)
A88: stacked-02-safe | B88: stacked | C88: SELECT * FROM orders WHERE id = 2; | D88: FALSE | E88: FALSE | F88: SAFE | G88: SAFE | H88: =IF(G88=F88,"PASS","FAIL") -> PASS | I88: - | J88: - | K88: SAFE | M88: First test pass (23 Sep)
A89: stacked-03 | B89: stacked | C89: SELECT * FROM invoices WHERE id = 3; DROP TABLE invoices; | D89: FALSE | E89: FALSE | F89: BLOCKED | G89: BLOCKED | H89: =IF(G89=F89,"PASS","FAIL") -> PASS | I89: stacked_statements, parse_error | J89: stacked_statements: Multiple SQL statements found in one request, parse_error: Multiple statements (2) in a single request are not allowed | K89: BLOCKED | L89: Now also reports stacked_statements (first pass only said parse_error). | M89: First test pass (23 Sep)
A90: stacked-03-safe | B90: stacked | C90: SELECT * FROM invoices WHERE id = 3; | D90: FALSE | E90: FALSE | F90: SAFE | G90: SAFE | H90: =IF(G90=F90,"PASS","FAIL") -> PASS | I90: - | J90: - | K90: SAFE | M90: First test pass (23 Sep)
A91: stacked-04 | B91: stacked | C91: SELECT * FROM employees WHERE id = 4; DROP TABLE employees; | D91: FALSE | E91: FALSE | F91: BLOCKED | G91: BLOCKED | H91: =IF(G91=F91,"PASS","FAIL") -> PASS | I91: stacked_statements, parse_error | J91: stacked_statements: Multiple SQL statements found in one request, parse_error: Multiple statements (2) in a single request are not allowed | K91: BLOCKED | L91: Now also reports stacked_statements (first pass only said parse_error). | M91: First test pass (23 Sep)
A92: stacked-04-safe | B92: stacked | C92: SELECT * FROM employees WHERE id = 4; | D92: FALSE | E92: FALSE | F92: SAFE | G92: SAFE | H92: =IF(G92=F92,"PASS","FAIL") -> PASS | I92: - | J92: - | K92: SAFE | M92: First test pass (23 Sep)
A93: stacked-05 | B93: stacked | C93: SELECT * FROM salaries WHERE id = 5; DROP TABLE salaries; | D93: FALSE | E93: FALSE | F93: BLOCKED | G93: BLOCKED | H93: =IF(G93=F93,"PASS","FAIL") -> PASS | I93: stacked_statements, parse_error | J93: stacked_statements: Multiple SQL statements found in one request, parse_error: Multiple statements (2) in a single request are not allowed | K93: BLOCKED | L93: Now also reports stacked_statements (first pass only said parse_error). | M93: First test pass (23 Sep)
A94: stacked-05-safe | B94: stacked | C94: SELECT * FROM salaries WHERE id = 5; | D94: FALSE | E94: FALSE | F94: SAFE | G94: SAFE | H94: =IF(G94=F94,"PASS","FAIL") -> PASS | I94: - | J94: - | K94: SAFE | M94: First test pass (23 Sep)
A95: stacked-06 | B95: stacked | C95: SELECT * FROM products WHERE id = 6; DROP TABLE products; | D95: FALSE | E95: FALSE | F95: BLOCKED | G95: BLOCKED | H95: =IF(G95=F95,"PASS","FAIL") -> PASS | I95: stacked_statements, parse_error | J95: stacked_statements: Multiple SQL statements found in one request, parse_error: Multiple statements (2) in a single request are not allowed | K95: BLOCKED | L95: Now also reports stacked_statements (first pass only said parse_error). | M95: First test pass (23 Sep)
A96: stacked-06-safe | B96: stacked | C96: SELECT * FROM products WHERE id = 6; | D96: FALSE | E96: FALSE | F96: SAFE | G96: SAFE | H96: =IF(G96=F96,"PASS","FAIL") -> PASS | I96: - | J96: - | K96: SAFE | M96: First test pass (23 Sep)
A97: stacked-07 | B97: stacked | C97: SELECT * FROM sessions WHERE id = 7; DROP TABLE sessions; | D97: FALSE | E97: FALSE | F97: BLOCKED | G97: BLOCKED | H97: =IF(G97=F97,"PASS","FAIL") -> PASS | I97: stacked_statements, parse_error | J97: stacked_statements: Multiple SQL statements found in one request, parse_error: Multiple statements (2) in a single request are not allowed | K97: BLOCKED | L97: Now also reports stacked_statements (first pass only said parse_error). | M97: First test pass (23 Sep)
A98: stacked-07-safe | B98: stacked | C98: SELECT * FROM sessions WHERE id = 7; | D98: FALSE | E98: FALSE | F98: SAFE | G98: SAFE | H98: =IF(G98=F98,"PASS","FAIL") -> PASS | I98: - | J98: - | K98: SAFE | M98: First test pass (23 Sep)
A99: stacked-08 | B99: stacked | C99: SELECT * FROM accounts WHERE id = 8; DROP TABLE accounts; | D99: FALSE | E99: FALSE | F99: BLOCKED | G99: BLOCKED | H99: =IF(G99=F99,"PASS","FAIL") -> PASS | I99: stacked_statements, parse_error | J99: stacked_statements: Multiple SQL statements found in one request, parse_error: Multiple statements (2) in a single request are not allowed | K99: BLOCKED | L99: Now also reports stacked_statements (first pass only said parse_error). | M99: First test pass (23 Sep)
A100: stacked-08-safe | B100: stacked | C100: SELECT * FROM accounts WHERE id = 8; | D100: FALSE | E100: FALSE | F100: SAFE | G100: SAFE | H100: =IF(G100=F100,"PASS","FAIL") -> PASS | I100: - | J100: - | K100: SAFE | M100: First test pass (23 Sep)
A101: tautology-01 | B101: tautology | C101: SELECT * FROM users WHERE 1=1; | D101: FALSE | E101: FALSE | F101: BLOCKED | G101: BLOCKED | H101: =IF(G101=F101,"PASS","FAIL") -> PASS | I101: tautology_predicate | J101: tautology_predicate: Always-true condition makes a WHERE/HAVING/ON filter match every row | K101: BLOCKED | L101: Message now says the check covers WHERE, HAVING and JOIN ... ON. | M101: First test pass (23 Sep)
A102: tautology-02 | B102: tautology | C102: SELECT * FROM users WHERE username = 'admin' OR 'a'='a'; | D102: FALSE | E102: FALSE | F102: BLOCKED | G102: BLOCKED | H102: =IF(G102=F102,"PASS","FAIL") -> PASS | I102: tautology_predicate | J102: tautology_predicate: Always-true condition makes a WHERE/HAVING/ON filter match every row | K102: BLOCKED | L102: Message now says the check covers WHERE, HAVING and JOIN ... ON. | M102: First test pass (23 Sep)
A103: tautology-03 | B103: tautology | C103: SELECT * FROM customers WHERE name = '' OR '1'='1'; | D103: FALSE | E103: FALSE | F103: BLOCKED | G103: BLOCKED | H103: =IF(G103=F103,"PASS","FAIL") -> PASS | I103: tautology_predicate | J103: tautology_predicate: Always-true condition makes a WHERE/HAVING/ON filter match every row | K103: BLOCKED | L103: Message now says the check covers WHERE, HAVING and JOIN ... ON. | M103: First test pass (23 Sep)
A104: tautology-04 | B104: tautology | C104: DELETE FROM sessions WHERE 1=1 OR user_id = 5; | D104: FALSE | E104: FALSE | F104: BLOCKED | G104: BLOCKED | H104: =IF(G104=F104,"PASS","FAIL") -> PASS | I104: write_not_authorized, tautology_predicate | J104: write_not_authorized: DELETE, tautology_predicate: Always-true condition makes a WHERE/HAVING/ON filter match every row | K104: BLOCKED | L104: Message now says the check covers WHERE, HAVING and JOIN ... ON. | M104: First test pass (23 Sep)
A105: tautology-05 | B105: tautology | C105: SELECT * FROM accounts WHERE id = 1 OR 2=2; | D105: FALSE | E105: FALSE | F105: BLOCKED | G105: BLOCKED | H105: =IF(G105=F105,"PASS","FAIL") -> PASS | I105: tautology_predicate | J105: tautology_predicate: Always-true condition makes a WHERE/HAVING/ON filter match every row | K105: BLOCKED | L105: Message now says the check covers WHERE, HAVING and JOIN ... ON. | M105: First test pass (23 Sep)
A106: tautology-06 | B106: tautology | C106: SELECT * FROM orders WHERE status = 'x' OR 'y'='y'; | D106: FALSE | E106: FALSE | F106: BLOCKED | G106: BLOCKED | H106: =IF(G106=F106,"PASS","FAIL") -> PASS | I106: tautology_predicate | J106: tautology_predicate: Always-true condition makes a WHERE/HAVING/ON filter match every row | K106: BLOCKED | L106: Message now says the check covers WHERE, HAVING and JOIN ... ON. | M106: First test pass (23 Sep)
A107: tautology-07 | B107: tautology | C107: SELECT * FROM payments WHERE amount > 0 OR 5=5; | D107: FALSE | E107: FALSE | F107: BLOCKED | G107: BLOCKED | H107: =IF(G107=F107,"PASS","FAIL") -> PASS | I107: tautology_predicate | J107: tautology_predicate: Always-true condition makes a WHERE/HAVING/ON filter match every row | K107: BLOCKED | L107: Message now says the check covers WHERE, HAVING and JOIN ... ON. | M107: First test pass (23 Sep)
A108: tautology-08 | B108: tautology | C108: SELECT * FROM employees WHERE dept = 'sales' OR 'z'='z'; | D108: FALSE | E108: FALSE | F108: BLOCKED | G108: BLOCKED | H108: =IF(G108=F108,"PASS","FAIL") -> PASS | I108: tautology_predicate | J108: tautology_predicate: Always-true condition makes a WHERE/HAVING/ON filter match every row | K108: BLOCKED | L108: Message now says the check covers WHERE, HAVING and JOIN ... ON. | M108: First test pass (23 Sep)
A109: tautology-09 | B109: tautology | C109: SELECT * FROM tickets WHERE priority = 'low' OR 3=3; | D109: FALSE | E109: FALSE | F109: BLOCKED | G109: BLOCKED | H109: =IF(G109=F109,"PASS","FAIL") -> PASS | I109: tautology_predicate | J109: tautology_predicate: Always-true condition makes a WHERE/HAVING/ON filter match every row | K109: BLOCKED | L109: Message now says the check covers WHERE, HAVING and JOIN ... ON. | M109: First test pass (23 Sep)
A110: tautology-10 | B110: tautology | C110: SELECT * FROM invoices WHERE paid = 0 OR 'admin'='admin'; | D110: FALSE | E110: FALSE | F110: BLOCKED | G110: BLOCKED | H110: =IF(G110=F110,"PASS","FAIL") -> PASS | I110: tautology_predicate | J110: tautology_predicate: Always-true condition makes a WHERE/HAVING/ON filter match every row | K110: BLOCKED | L110: Message now says the check covers WHERE, HAVING and JOIN ... ON. | M110: First test pass (23 Sep)
...
